<?xml version="1.0" encoding="UTF-8"?>
<!-- Generated by org.testng.reporters.JUnitReportReporter -->
<testsuite skipped="2" hostname="Rahul-PC" name="org.devlab.ui.testbed.LoginTest" tests="4" failures="1" timestamp="2020-05-17T02:00:33 IST" time="42.003" errors="0">
  <testcase name="Login_with_with_set_of_valid_data" time="8.950" classname="org.devlab.ui.testbed.LoginTest"/>
  <system-out/>
  <testcase name="Login_with_with_set_of_Invalid_data" time="13.060" classname="org.devlab.ui.testbed.LoginTest">
    <skipped/>
  </testcase> <!-- Login_with_with_set_of_Invalid_data -->
  <system-out/>
  <testcase name="Login_with_with_set_of_Invalid_data" time="12.326" classname="org.devlab.ui.testbed.LoginTest">
    <skipped/>
  </testcase> <!-- Login_with_with_set_of_Invalid_data -->
  <system-out/>
  <testcase name="Login_with_with_set_of_Invalid_data" time="7.667" classname="org.devlab.ui.testbed.LoginTest">
    <failure type="java.lang.AssertionError" message="Failed to login into application with valid set of user :StageUser:StagePwd expected [false] but found [true]">
      <![CDATA[java.lang.AssertionError: Failed to login into application with valid set of user :StageUser:StagePwd expected [false] but found [true]
at org.testng.Assert.fail(Assert.java:97)
at org.testng.Assert.failNotEquals(Assert.java:968)
at org.testng.Assert.assertFalse(Assert.java:65)
at org.devlab.ui.testbed.LoginTest.Login_with_with_set_of_Invalid_data(LoginTest.java:50)
at sun.reflect.NativeMethodAccessorImpl.invoke0(Native Method)
at sun.reflect.NativeMethodAccessorImpl.invoke(NativeMethodAccessorImpl.java:62)
at sun.reflect.DelegatingMethodAccessorImpl.invoke(DelegatingMethodAccessorImpl.java:43)
at java.lang.reflect.Method.invoke(Method.java:498)
at org.testng.internal.MethodInvocationHelper.invokeMethod(MethodInvocationHelper.java:135)
at org.testng.internal.TestInvoker.invokeMethod(TestInvoker.java:598)
at org.testng.internal.TestInvoker.retryFailed(TestInvoker.java:214)
at org.testng.internal.MethodRunner.runInSequence(MethodRunner.java:58)
at org.testng.internal.TestInvoker$MethodInvocationAgent.invoke(TestInvoker.java:821)
at org.testng.internal.TestInvoker.invokeTestMethods(TestInvoker.java:147)
at org.testng.internal.TestMethodWorker.invokeTestMethods(TestMethodWorker.java:146)
at org.testng.internal.TestMethodWorker.run(TestMethodWorker.java:128)
at java.util.concurrent.ThreadPoolExecutor.runWorker(ThreadPoolExecutor.java:1149)
at java.util.concurrent.ThreadPoolExecutor$Worker.run(ThreadPoolExecutor.java:624)
at java.lang.Thread.run(Thread.java:748)
]]>
    </failure>
  </testcase> <!-- Login_with_with_set_of_Invalid_data -->
  <system-out/>
</testsuite> <!-- org.devlab.ui.testbed.LoginTest -->
